[2024-12-07 02:08:30,981][src.utils.utils][INFO] - [rank: 0] Enforcing tags! <cfg.extras.enforce_tags=True>
[2024-12-07 02:08:31,001][src.utils.utils][INFO] - [rank: 0] Printing config tree with Rich! <cfg.extras.print_config=True>
[2024-12-07 02:08:31,099][__main__][INFO] - [rank: 0] Instantiating datamodule <src.data.ImageCaptionDataModule>
[2024-12-07 02:08:31,604][__main__][INFO] - [rank: 0] Instantiating model <src.models.ImageCaptionModule>
[2024-12-07 02:08:35,715][__main__][INFO] - [rank: 0] Instantiating callbacks...
[2024-12-07 02:08:35,715][src.utils.instantiators][INFO] - [rank: 0] Instantiating callback <lightning.pytorch.callbacks.ModelCheckpoint>
[2024-12-07 02:08:35,719][src.utils.instantiators][INFO] - [rank: 0] Instantiating callback <lightning.pytorch.callbacks.EarlyStopping>
[2024-12-07 02:08:35,721][src.utils.instantiators][INFO] - [rank: 0] Instantiating callback <lightning.pytorch.callbacks.RichModelSummary>
[2024-12-07 02:08:35,722][src.utils.instantiators][INFO] - [rank: 0] Instantiating callback <lightning.pytorch.callbacks.RichProgressBar>
[2024-12-07 02:08:35,722][__main__][INFO] - [rank: 0] Instantiating loggers...
[2024-12-07 02:08:35,722][src.utils.instantiators][INFO] - [rank: 0] Instantiating logger <lightning.pytorch.loggers.wandb.WandbLogger>
[2024-12-07 02:08:35,732][__main__][INFO] - [rank: 0] Instantiating trainer <lightning.pytorch.trainer.Trainer>
[2024-12-07 02:08:35,772][__main__][INFO] - [rank: 0] Logging hyperparameters!
[2024-12-07 02:08:38,720][__main__][INFO] - [rank: 0] Starting training!
[2024-12-07 02:27:44,821][src.utils.utils][ERROR] - [rank: 0] 
Traceback (most recent call last):
  File "C:\anaconda3\envs\image-caption\lib\site-packages\torch\utils\data\dataloader.py", line 1243, in _try_get_data
    data = self._data_queue.get(timeout=timeout)
  File "C:\anaconda3\envs\image-caption\lib\queue.py", line 179, in get
    raise Empty
_queue.Empty

The above exception was the direct cause of the following exception:

Traceback (most recent call last):
  File "C:\Image-Captioning\src\utils\utils.py", line 68, in wrap
    metric_dict, object_dict = task_func(cfg=cfg)
  File "C:\Image-Captioning\src\train.py", line 87, in train
    trainer.fit(model=model, datamodule=datamodule, ckpt_path=cfg.get("ckpt_path"))
  File "C:\anaconda3\envs\image-caption\lib\site-packages\lightning\pytorch\trainer\trainer.py", line 538, in fit
    call._call_and_handle_interrupt(
  File "C:\anaconda3\envs\image-caption\lib\site-packages\lightning\pytorch\trainer\call.py", line 47, in _call_and_handle_interrupt
    return trainer_fn(*args, **kwargs)
  File "C:\anaconda3\envs\image-caption\lib\site-packages\lightning\pytorch\trainer\trainer.py", line 574, in _fit_impl
    self._run(model, ckpt_path=ckpt_path)
  File "C:\anaconda3\envs\image-caption\lib\site-packages\lightning\pytorch\trainer\trainer.py", line 981, in _run
    results = self._run_stage()
  File "C:\anaconda3\envs\image-caption\lib\site-packages\lightning\pytorch\trainer\trainer.py", line 1025, in _run_stage
    self.fit_loop.run()
  File "C:\anaconda3\envs\image-caption\lib\site-packages\lightning\pytorch\loops\fit_loop.py", line 205, in run
    self.advance()
  File "C:\anaconda3\envs\image-caption\lib\site-packages\lightning\pytorch\loops\fit_loop.py", line 363, in advance
    self.epoch_loop.run(self._data_fetcher)
  File "C:\anaconda3\envs\image-caption\lib\site-packages\lightning\pytorch\loops\training_epoch_loop.py", line 140, in run
    self.advance(data_fetcher)
  File "C:\anaconda3\envs\image-caption\lib\site-packages\lightning\pytorch\loops\training_epoch_loop.py", line 212, in advance
    batch, _, __ = next(data_fetcher)
  File "C:\anaconda3\envs\image-caption\lib\site-packages\lightning\pytorch\loops\fetchers.py", line 133, in __next__
    batch = super().__next__()
  File "C:\anaconda3\envs\image-caption\lib\site-packages\lightning\pytorch\loops\fetchers.py", line 60, in __next__
    batch = next(self.iterator)
  File "C:\anaconda3\envs\image-caption\lib\site-packages\lightning\pytorch\utilities\combined_loader.py", line 341, in __next__
    out = next(self._iterator)
  File "C:\anaconda3\envs\image-caption\lib\site-packages\lightning\pytorch\utilities\combined_loader.py", line 78, in __next__
    out[i] = next(self.iterators[i])
  File "C:\anaconda3\envs\image-caption\lib\site-packages\torch\utils\data\dataloader.py", line 701, in __next__
    data = self._next_data()
  File "C:\anaconda3\envs\image-caption\lib\site-packages\torch\utils\data\dataloader.py", line 1448, in _next_data
    idx, data = self._get_data()
  File "C:\anaconda3\envs\image-caption\lib\site-packages\torch\utils\data\dataloader.py", line 1402, in _get_data
    success, data = self._try_get_data()
  File "C:\anaconda3\envs\image-caption\lib\site-packages\torch\utils\data\dataloader.py", line 1256, in _try_get_data
    raise RuntimeError(
RuntimeError: DataLoader worker (pid(s) 18408) exited unexpectedly
[2024-12-07 02:27:44,851][src.utils.utils][INFO] - [rank: 0] Output dir: C:\Image-Captioning\logs\train\runs\2024-12-07_02-08-30
[2024-12-07 02:27:44,852][src.utils.utils][INFO] - [rank: 0] Closing wandb!
