[2024-12-07 01:28:31,316][src.utils.utils][INFO] - [rank: 0] Enforcing tags! <cfg.extras.enforce_tags=True>
[2024-12-07 01:28:31,324][src.utils.utils][INFO] - [rank: 0] Printing config tree with Rich! <cfg.extras.print_config=True>
[2024-12-07 01:28:31,403][__main__][INFO] - [rank: 0] Instantiating datamodule <src.data.ImageCaptionDataModule>
[2024-12-07 01:28:31,904][__main__][INFO] - [rank: 0] Instantiating model <src.models.ImageCaptionModule>
[2024-12-07 01:28:35,990][__main__][INFO] - [rank: 0] Instantiating callbacks...
[2024-12-07 01:28:35,990][src.utils.instantiators][INFO] - [rank: 0] Instantiating callback <lightning.pytorch.callbacks.ModelCheckpoint>
[2024-12-07 01:28:35,994][src.utils.instantiators][INFO] - [rank: 0] Instantiating callback <lightning.pytorch.callbacks.EarlyStopping>
[2024-12-07 01:28:35,995][src.utils.instantiators][INFO] - [rank: 0] Instantiating callback <lightning.pytorch.callbacks.RichModelSummary>
[2024-12-07 01:28:35,996][src.utils.instantiators][INFO] - [rank: 0] Instantiating callback <lightning.pytorch.callbacks.RichProgressBar>
[2024-12-07 01:28:35,997][__main__][INFO] - [rank: 0] Instantiating loggers...
[2024-12-07 01:28:35,997][src.utils.instantiators][INFO] - [rank: 0] Instantiating logger <lightning.pytorch.loggers.wandb.WandbLogger>
[2024-12-07 01:28:36,003][__main__][INFO] - [rank: 0] Instantiating trainer <lightning.pytorch.trainer.Trainer>
[2024-12-07 01:28:36,010][src.utils.utils][ERROR] - [rank: 0] 
Traceback (most recent call last):
  File "C:\anaconda3\envs\image-caption\lib\site-packages\hydra\_internal\instantiate\_instantiate2.py", line 92, in _call_target
    return _target_(*args, **kwargs)
  File "C:\anaconda3\envs\image-caption\lib\site-packages\lightning\pytorch\utilities\argparse.py", line 70, in insert_env_defaults
    return fn(self, **kwargs)
  File "C:\anaconda3\envs\image-caption\lib\site-packages\lightning\pytorch\trainer\trainer.py", line 395, in __init__
    self._accelerator_connector = _AcceleratorConnector(
  File "C:\anaconda3\envs\image-caption\lib\site-packages\lightning\pytorch\trainer\connectors\accelerator_connector.py", line 143, in __init__
    self._accelerator_flag = self._choose_gpu_accelerator_backend()
  File "C:\anaconda3\envs\image-caption\lib\site-packages\lightning\pytorch\trainer\connectors\accelerator_connector.py", line 353, in _choose_gpu_accelerator_backend
    raise MisconfigurationException("No supported gpu backend found!")
lightning.fabric.utilities.exceptions.MisconfigurationException: No supported gpu backend found!

The above exception was the direct cause of the following exception:

Traceback (most recent call last):
  File "C:\Image-Captioning\src\utils\utils.py", line 68, in wrap
    metric_dict, object_dict = task_func(cfg=cfg)
  File "C:\Image-Captioning\src\train.py", line 70, in train
    trainer: Trainer = hydra.utils.instantiate(cfg.trainer, callbacks=callbacks, logger=logger)
  File "C:\anaconda3\envs\image-caption\lib\site-packages\hydra\_internal\instantiate\_instantiate2.py", line 226, in instantiate
    return instantiate_node(
  File "C:\anaconda3\envs\image-caption\lib\site-packages\hydra\_internal\instantiate\_instantiate2.py", line 347, in instantiate_node
    return _call_target(_target_, partial, args, kwargs, full_key)
  File "C:\anaconda3\envs\image-caption\lib\site-packages\hydra\_internal\instantiate\_instantiate2.py", line 97, in _call_target
    raise InstantiationException(msg) from e
hydra.errors.InstantiationException: Error in call to target 'lightning.pytorch.trainer.trainer.Trainer':
MisconfigurationException('No supported gpu backend found!')
full_key: trainer
[2024-12-07 01:28:36,020][src.utils.utils][INFO] - [rank: 0] Output dir: C:\Image-Captioning\logs\train\runs\2024-12-07_01-28-31
